<?xml version="1.0" encoding="UTF-8"?>
<!-- Generated by org.testng.reporters.JUnitXMLReporter -->
<testsuite hostname="Denis-PC" ignored="2" name="PowSqrtTest" tests="11" failures="3" timestamp="04 июн 2017 13:27:07 GMT" time="0.016" errors="0">
  <testcase name="testPowDouble" time="0.0" classname="testng.calculator.PowTest"/>
  <testcase name="testPowDouble" time="0.0" classname="testng.calculator.PowTest"/>
  <testcase name="testPowDouble" time="0.0" classname="testng.calculator.PowTest"/>
  <testcase name="testPowDouble" time="0.0" classname="testng.calculator.PowTest"/>
  <testcase name="testPowDouble" time="0.0" classname="testng.calculator.PowTest">
    <failure type="java.lang.AssertionError" message="expected [4.84] but found [4.840000000000001]">
      <![CDATA[java.lang.AssertionError: expected [4.84] but found [4.840000000000001]
	at testng.calculator.PowTest.testPowDouble(PowTest.java:14)
	at testng.runner.TestRunner.main(TestRunner.java:33)
	at com.intellij.rt.execution.application.AppMain.main(AppMain.java:147)
... Removed 32 stack frames]]>
    </failure>
  </testcase> <!-- testPowDouble -->
  <testcase name="testPowDouble" time="0.0" classname="testng.calculator.PowTest">
    <failure type="java.lang.AssertionError" message="expected [3.0] but found [1.0]">
      <![CDATA[java.lang.AssertionError: expected [3.0] but found [1.0]
	at testng.calculator.PowTest.testPowDouble(PowTest.java:14)
	at testng.runner.TestRunner.main(TestRunner.java:33)
	at com.intellij.rt.execution.application.AppMain.main(AppMain.java:147)
... Removed 32 stack frames]]>
    </failure>
  </testcase> <!-- testPowDouble -->
  <testcase name="negativeArg" time="0.0" classname="testng.calculator.SqrtTest">
    <failure type="org.testng.TestException" message="
Method SqrtTest.negativeArg()[pri:0, instance:testng.calculator.SqrtTest@4f4a7090] should have thrown an exception of type class java.lang.NumberFormatException">
      <![CDATA[org.testng.TestException: 
Method SqrtTest.negativeArg()[pri:0, instance:testng.calculator.SqrtTest@4f4a7090] should have thrown an exception of type class java.lang.NumberFormatException
	at testng.runner.TestRunner.main(TestRunner.java:33)
	at com.intellij.rt.execution.application.AppMain.main(AppMain.java:147)
... Removed 24 stack frames]]>
    </failure>
  </testcase> <!-- negativeArg -->
  <testcase name="testSqrtDouble" time="0.0" classname="testng.calculator.SqrtTest"/>
  <testcase name="testSqrtDouble" time="0.0" classname="testng.calculator.SqrtTest"/>
  <testcase name="testSqrtDouble" time="0.016" classname="testng.calculator.SqrtTest"/>
  <testcase name="testSqrtDouble" time="0.0" classname="testng.calculator.SqrtTest"/>
  <testcase name="@BeforeSuite setPhrase" time="0.0" classname="testng.calculator.BaseTest">
    <ignored/>
  </testcase> <!-- @BeforeSuite setPhrase -->
  <testcase name="@AfterSuite setPhraseDone" time="0.0" classname="testng.calculator.BaseTest">
    <ignored/>
  </testcase> <!-- @AfterSuite setPhraseDone -->
</testsuite> <!-- PowSqrtTest -->
